Workbook

Sheet README
A1: McEasy — FMS comparables benchmark
B3: Built for | C3: Grady Kusmulyadi, McEasy — benchmarking a 2030 target of USD100m ARR.
B4: Built on | C4: 10-Aug-2026. Latest reported full year for each company.
B5: Peer set | C5: Emerging-market SMB fleet operators (Karooooo/Cartrack, Ituran, Powerfleet incl. MiX Telematics history), private VC-backed FMS (Motive, Geotab, Lytx, Gurtam), and the players currently at USD80-250m of revenue (Microlise, CalAmp, Teletrac Navman, Netradyne, ORBCOMM), plus Chinese-listed hardware vendors (Queclink, Streamax) in a separate block and two below-band closest-model comps (Quartix, Fleetio).
B6: Three cuts | C6: The workbook answers the USD100m question three ways, and they disagree with each other in the most useful way possible: what USD100m ARR looked like historically (Cartrack FY2019), who is at that size right now (Microlise, Quartix and peers), and where the big players sit today (Karooooo, Motive, Powerfleet, Ituran).
B8: Sheets
B9: McEasy vs Benchmark | C9: THE ANSWER. McEasy's 2030 model against Cartrack FY2019, with the per-vehicle unit economics that carry the argument, the one claim that needs defending, and bull/base/bear. Start here.
B10: Conservative Cases | C10: 2030 revenue $10m and $20m below plan, re-based month by month from Jul-2026 off actuals. Two drivers each, because a volume miss and a price miss end up in different places. Includes the 2027 cash trough.
B11: Capex Decomposition | C11: The one claim that needs defending, taken apart. Capex per NEW INSTALL (USD54) against a bottom-up bill of materials (USD26-46), why Cartrack's USD177 is not a device cost, and the justifications ranked.
B12: Growth Reality Check | C12: The assumption that IS more aggressive than the benchmark — a 66% ARR CAGR delivered while turning profitable and not raising again.
B13: McEasy Model | C13: Grady's own model, read programmatically from the source file. Yellow cell = the 2030 vehicle count, which drives every per-vehicle figure.
B14: At 100M (Today) | C14: WHO IS AT THIS SIZE RIGHT NOW — revenue USD80-250m. Three labelled blocks: subscription-FMS operators, hardware vendors, and below-band closest models. Start here.
B15: At 100M (Historic) | C15: The same metrics at the year each company crossed ~USD100m ARR. Cartrack FY2019 is the only fully-populated row.
B16: Current Position | C16: The big players at their latest reported year — the destination view. All in USD millions.
B17: Valuation Signals | C17: What the market pays for an FMS business at USD100-250m of revenue, and what it depends on. The dispersion is roughly 20x wide.
B18: Revenue by Country | C18: Geographic mix across every company that discloses one. Karooooo FY2019 and FY2025 disclosed, FY2026 rolled forward; plus Queclink, Streamax, Ituran, Motive and Cartrack subscribers by region.
B19: Revenue by Product | C19: Product-line mix. Recurring versus hardware, Karooooo's Delivery-as-a-Service drag, and Queclink's full device line-up.
B20: Karooooo Path | C20: Cartrack FY2018 to FY2026 in full — the actual trajectory from USD90m to USD325m ARR.
... B23: Sources | C23: Every URL, with what it supports.
B25: The answer, in one paragraph
C26: Cartrack at FY2019 is the benchmark, and the match is far closer than a margin comparison suggests. McEasy's 2030 plan and Cartrack's FY2019 actuals sit 1.1% apart on vehicles (950,000 vs 960,798) and 2.3% apart on EBITDA per vehicle ($56.54 vs $57.85) — at a LOWER price per vehicle ($8.94/month vs $10.72). The 7.7pp EBITDA margin gap is a denominator effect from carrying less low-margin hardware revenue, not a claim to superior operating performance. That collapses the whole investor challenge to one testable number: capex per vehicle of $20.00 against Cartrack's $38.53. Lead with EBITDA per vehicle, never with 52.7%.
B28: Seven things the data says
B29: 1 | C29: USD100m ARR is not one destination — it is at least three different businesses. At that milestone, EBITDA margin across this peer set ranged from roughly 21% (MiX Telematics) to 45% (Cartrack) to deeply negative (Motive), and time from founding ranged from 6 years to 18. Decide which one you are building before you plan the number.
B30: 2 | C30: The company closest to USD100m ARR today is a warning, not a target. Microlise runs ARR of USD78m on USD111m of revenue with a 64% gross margin — and posts a STATUTORY OPERATING LOSS. Its 10% figure is adjusted EBITDA, down from 14%. Cartrack at a comparable ARR in FY2019 ran a 45% EBITDA margin and a 21% net margin. Same scale, same industry, opposite economics.
B31: 3 | C31: The market prices that difference brutally. Microlise carries an enterprise value of 0.39x sales — GBP32m against GBP84m of revenue. Karooooo carries 5.52x. Teletrac Navman, at USD168m of revenue, was sold by a strategic owner for about 1.3x. CalAmp reached USD200m of revenue and 2.7m subscribers, then wiped out its equity in Chapter 11 on a 6.4% EBITDA margin. Reaching USD100m ARR at thin margins creates almost no enterprise value.
B32: 4 | C32: Scale is not what creates margin. Quartix is profitable at HALF the target size — 73% gross, 24% operating, 18% net, 12.5% FCF margin on USD47m of revenue. Pricing power and product mix create margin; revenue does not.
B33: 5 | C33: Cartrack's free-cash-flow margin at USD100m ARR was about 2%, not the 15% it runs today. A 45% EBITDA margin was almost entirely consumed by capex running at 30% of revenue — devices, installation and contract assets. Hardware-subsidised FMS does not self-fund at USD100m.
B34: 6 | C34: Geographic diversification did not drive Cartrack from USD100m to USD325m. South Africa was 73.6% of revenue at the milestone and is still about 74% today; Southeast Asia is 12.6% of the subscriber base after roughly fifteen years. Depth in the home market, not breadth, was the engine. Note the mirror image: Queclink, a device vendor, earns 94% of revenue outside its home market. Exporting hardware and operating a subscription base are different businesses.
B35: 7 | C35: Karooooo management states plainly that Southeast Asian ARPU — Indonesia, Philippines, Thailand — sits materially below South African ARPU and will dilute group ARPU as the mix shifts. For an Indonesia-based company this is the binding constraint, and it makes the subscriber count, not the ARR figure, the real target.
B37: One caution on the framing
C38: Karooooo's current position — USD325m ARR, 18% net margin, 15% FCF margin, dividend-paying — is the destination, not the path, and benchmarking against it will flatter any 2030 model. Those margins reflect twenty-two years of compounding and a dominant position in one market. But the opposite error is just as costly: benchmarking against today's USD100m players alone would suggest the milestone is barely worth reaching. The honest reading needs both. And the real conclusion is that "USD100m ARR by 2030" is an underspecified goal — the same ARR is worth roughly USD40m of enterprise value at Microlise economics and several hundred million at Cartrack economics. Specify the margin alongside the ARR.
B40: Colour convention
C41: Blue — a figure taken from a source, or an input you can change.
C42: Black — calculated on this sheet.
C43: Green — links to another sheet in this workbook.
C44: Yellow fill — fill this in with your own numbers.
C45: Grey / blank — not disclosed. Deliberately left empty.

Sheet McEasy vs Benchmark
A1: McEasy 2030 against Cartrack FY2019 — the investor argument
A2: Cartrack crossed USD111m subscription ARR in FY2019 with 960,798 subscribers. McEasy targets USD100.9m ARR in 2030 with ~950k vehicles. Read the per-vehicle block, not the margin block.
A4: Block 1 — margin comparison. This is the block that invites the attack.
A5: Metric | B5: McEasy 2030 | C5: Cartrack FY2019 | D5: Delta | E5: Comment
A6: ARR (USD m) | B6: ='McEasy Model'!J7/1000000 -> 100.9007 | C6: ='Karooooo Path'!C23 -> 110.9854 | D6: =IF(COUNT(B6,C6)=2,B6-C6,"") -> -10.084703 | E6: Within 9%. Cartrack's is subscription revenue, the closest disclosed analogue to ARR.
A7: Total revenue (USD m) | B7: ='McEasy Model'!J10/1000000 -> 101.89465 | C7: ='Karooooo Path'!C22 -> 123.55474 | D7: =IF(COUNT(B7,C7)=2,B7-C7,"") -> -21.660091 | E7: McEasy earns less total revenue at the same subscriber count — see the ARPU row below.
A8: Gross margin | B8: ='McEasy Model'!J34 -> 0.65882156 | D8: =IF(COUNT(B8,C8)=2,B8-C8,"") | E8: Cartrack did not disclose gross profit in FY2019. Karooooo's Cartrack segment runs 72% today against McEasy's 75.6% SaaS-only line — near-identical software unit economics.
A9: EBITDA margin | B9: ='McEasy Model'!J37 -> 0.52717598 | C9: ='Karooooo Path'!C32 -> 0.44981391 | D9: =IF(COUNT(B9,C9)=2,B9-C9,"") -> 0.077362073 | E9: THE headline gap: 7.7pp. Do not lead with this number. Block 2 explains why it is a denominator effect.
A10: Net margin | B10: ='McEasy Model'!J40 -> 0.32202887 | C10: ='Karooooo Path'!C31 -> 0.21326874 | D10: =IF(COUNT(B10,C10)=2,B10-C10,"") -> 0.10876013 | E10: 10.9pp gap, entirely attributable to lower depreciation per vehicle.
A11: Depreciation % of revenue | B11: ='McEasy Model'!J38 -> 0.11360255 | C11: ='Karooooo Path'!C32-'Karooooo Path'!C30 -> 0.15448691 | D11: =IF(COUNT(B11,C11)=2,B11-C11,"") -> -0.040884369 | E11: Cartrack's is EBITDA margin less operating margin. McEasy carries a lighter asset base.
A12: Capex % of revenue | B12: ='McEasy Model'!J39 -> 0.18649777 | C12: ='Karooooo Path'!C34 -> 0.29963963 | D12: =IF(COUNT(B12,C12)=2,B12-C12,"") -> -0.11314186 | E12: 11.4pp lighter. The single most important assumption in the whole plan.
A13: Recurring % of revenue | B13: ='McEasy Model'!J8/'McEasy Model'!J10 -> 0.82147645 | C13: ='Karooooo Path'!C35 -> 0.89826904 | D13: =IF(COUNT(B13,C13)=2,B13-C13,"") -> -0.07679259 | E13: 82.1% versus 89.8%. McEasy carries more low-margin spareparts revenue, which is exactly what drags the gross margin and flatters the EBITDA margin.
A15: Block 2 — per vehicle per year. THIS IS THE ARGUMENT.
A16: Metric | B16: McEasy 2030 | C16: Cartrack FY2019 | D16: Delta % | E16: Comment
A17: Vehicles / subscribers | B17: ='McEasy Model'!$B$44 -> 950000 | C17: ='Karooooo Path'!C19 -> 960798 | D17: =IF(AND(COUNT(B17,C17)=2,C17<>0),B17/C17-1,"") -> -0.011238575 | E17: 950,000 against 960,798 — 1.1% apart. Not approximately the same scale; the same scale.
A18: Revenue | B18: ='McEasy Model'!J10/'McEasy Model'!$B$44 -> 107.25753 | C18: =('Karooooo Path'!C22*1000000)/'Karooooo Path'!C19 -> 128.59596 | D18: =IF(AND(COUNT(B18,C18)=2,C18<>0),B18/C18-1,"") -> -0.16593393 | E18: McEasy earns ~17% less per vehicle, because it passes through less hardware revenue.
A19: SaaS / subscription revenue | B19: ='McEasy Model'!J8/'McEasy Model'!$B$44 -> 88.109535 | C19: =('Karooooo Path'!C23*1000000)/'Karooooo Path'!C19 -> 115.51377 | D19: =IF(AND(COUNT(B19,C19)=2,C19<>0),B19/C19-1,"") -> -0.23723784 | E19: ~24% less. McEasy is assuming LESS pricing power than the benchmark achieved, not more.
A20: EBITDA | B20: ='McEasy Model'!J22/'McEasy Model'!$B$44 -> 56.543594 | C20: =('Karooooo Path'!C25*1000000)/'Karooooo Path'!C19 -> 57.844253 | D20: =IF(AND(COUNT(B20,C20)=2,C20<>0),B20/C20-1,"") -> -0.022485538 | E20: 2.3% apart. The two businesses generate the same cash per vehicle. This single row answers the margin objection.
A21: Cash cost (revenue less EBITDA) | B21: =('McEasy Model'!J10-'McEasy Model'!J22)/'McEasy Model'!$B$44 -> 50.713937 | C21: =(('Karooooo Path'!C22*1000000)-('Karooooo Path'!C25*1000000))/'Karooooo Path'!C19 -> 70.751711 | D21: =IF(AND(COUNT(B21,C21)=2,C21<>0),B21/C21-1,"") -> -0.28321257 | E21: 28% lower. Defensible on Indonesian versus South African fully-loaded cost per head — but it needs a headcount plan behind it.
A22: Depreciation | B22: ='McEasy Model'!J23/'McEasy Model'!$B$44 -> 12.184729 | C22: =(('Karooooo Path'!C13-'Karooooo Path'!C11)/'Karooooo Path'!C6*1000000)/'Karooooo Path'!C19 -> 19.866394 | D22: =IF(AND(COUNT(B22,C22)=2,C22<>0),B22/C22-1,"") -> -0.38666631 | E22: 39% lower, and the direct cause of the net-margin gap.
A23: Capex | B23: ='McEasy Model'!J31/'McEasy Model'!$B$44 -> 20.00329 | C23: =('Karooooo Path'!C15/'Karooooo Path'!C6*1000000)/'Karooooo Path'!C19 -> 38.532447 | D23: =IF(AND(COUNT(B23,C23)=2,C23<>0),B23/C23-1,"") -> -0.48087153 | E23: 48% lower. This is the one claim an investor should test — see Block 3.
A24: Net profit | B24: ='McEasy Model'!J25/'McEasy Model'!$B$44 -> 34.540021 | C24: =('Karooooo Path'!C12/'Karooooo Path'!C6*1000000)/'Karooooo Path'!C19 -> 27.425499 | D24: =IF(AND(COUNT(B24,C24)=2,C24<>0),B24/C24-1,"") -> 0.25941267 | E24: 26% HIGHER, entirely explained by the lower depreciation above. One coherent story, not three unrelated stretches.
A25: ARPU — total revenue per month | B25: ='McEasy Model'!J10/'McEasy Model'!$B$44/12 -> 8.9381275 | C25: =('Karooooo Path'!C22*1000000)/'Karooooo Path'!C19/12 -> 10.71633 | D25: =IF(AND(COUNT(B25,C25)=2,C25<>0),B25/C25-1,"") -> -0.16593393 | E25: USD8.94 against USD10.72.
A26: ARPU — SaaS only per month | B26: ='McEasy Model'!J8/'McEasy Model'!$B$44/12 -> 7.3424612 | C26: =('Karooooo Path'!C23*1000000)/'Karooooo Path'!C19/12 -> 9.6261477 | D26: =IF(AND(COUNT(B26,C26)=2,C26<>0),B26/C26-1,"") -> -0.23723784 | E26: USD7.34 against USD9.63.
A28: Block 3 — the one remaining claim: cost per NEW INSTALL, not per base vehicle
A29: McEasy 2030 capex per NEW INSTALLATION | B29: ='McEasy Model'!J31/('McEasy Model'!$B$44-('McEasy Model'!$B$44*'McEasy Model'!I8/'McEasy Model'!J8)) -> 54.217886 | E29: Capex is spent on new units, not on the whole base. This is the correct denominator and the number to quote. Full derivation on the 'Capex Decomposition' sheet.
A30: Bottom-up bill of materials for one basic-tracker install | B30: $26 – $46 | E30: 4G Cat-1 tracker USD15-25 landed, installation labour USD8-15, SIM and logistics USD3-6. The model's budget sits ABOVE this — it carries headroom rather than being aggressive. That is the answer to the capex question.
A31: Cartrack FY2019 capex per net addition, as reported | B31: =('Karooooo Path'!C15/'Karooooo Path'!C6*1000000)/('Karooooo Path'!C19-'Karooooo Path'!B19) -> 176.7847 | E31: Not comparable as reported: the line is 'PP&E AND CONTRACT ASSETS' and bundles capitalised commissions with stolen-vehicle-recovery infrastructure — ground and air recovery teams, control rooms, recovery fleet. Strip 30-40% and it lands near USD106-124 per install.
A32: Supporting evidence and the counter-risks
A33: • | B33: Queclink, the listed device vendor: FY2025 revenue FELL 7.8% while gross margin compressed from 40.1% to 36.9% and operating margin collapsed from 13.4% to 5.4%. Streamax: revenue FELL 10.8%. A device maker losing pricing power is a device buyer gaining it. Both on 'At 100M (Today)'.
A34: • | B34: Your own accounts carry the strongest argument: Sparepart Solutions is USD18.2m of 2030 revenue at a 21.2% gross margin — pass-through hardware. A device the customer BUYS is cost of revenue, not capex. Cartrack subsidised and retained its devices, so its spend sat in PP&E. Say the flip side too: this relocates cost rather than removing it, which is why the blended gross margin is 65.9% against 75.6% SaaS-only — and why EBITDA per vehicle still matches.
A35: • | B35: Counter-risk one: on the per-install denominator the gap versus Cartrack as reported is about -69%, WIDER than the -48% a per-base-vehicle comparison implies. Concede this before an investor derives it, then point at the bill of materials.
A36: • | B36: Counter-risk two: at a blended dashcam install cost, only a single-digit percentage of new installs can be AI video units before this budget breaks. Check it against the product roadmap.
A37: • | B37: Counter-risk three: capex here is derived as the change in GROSS fixed assets, so it excludes device retirement and replacement. If churned devices are not recovered and reused, true capex per install is higher and this argument weakens.
A39: Block 4 — bull / base / bear, each anchored on a real comparable
A40: Scenario | B40: EBITDA margin | C40: EBITDA (USD m) | D40: Net (USD m) | E40: Anchor and implied enterprise value
A41: Bear — Microlise economics | B41: ='At 100M (Today)'!Q6 -> 0.1 | C41: =IFERROR(B41*'McEasy Model'!J10/1000000,"") -> 10.189465 | D41: =IFERROR('At 100M (Today)'!P6*'McEasy Model'!J10/1000000,"") -> -2.6313388 | E41: Microlise runs 10% adjusted EBITDA and a statutory operating loss at USD78m ARR, and trades at 0.39x sales. USD100m of ARR at these economics is worth about USD40m of enterprise value. This is the real downside and it is not theoretical.
A42: Base — Cartrack FY2019 economics | B42: ='Karooooo Path'!C32 -> 0.44981391 | C42: =IFERROR(B42*'McEasy Model'!J10/1000000,"") -> 45.833632 | D42: =IFERROR('Karooooo Path'!C31*'McEasy Model'!J10/1000000,"") -> 21.730945 | E42: 45.0% EBITDA and 21.3% net, valued on Quartix's 2.93x sales — a profitable, listed, modest-growth telematics business. The defensible ask: we match the best emerging-market comparable at the same scale.
A43: Bull — McEasy's own model | B43: ='McEasy Model'!J37 -> 0.52717598 | C43: =IFERROR(B43*'McEasy Model'!J10/1000000,"") -> 53.716414 | D43: =IFERROR('McEasy Model'!J40*'McEasy Model'!J10/1000000,"") -> 32.81302 | E43: 52.7% EBITDA and 32.2% net, valued on Karooooo's 5.70x sales. Requires the device-cost claim in Block 3 to hold AND the growth in the next sheet to be delivered.
A44: Implied enterprise value at the anchor's sales multiple (USD m) | B44: =IFERROR('Valuation Signals'!G11*'McEasy Model'!J10/1000000,"") -> 39.227562 | C44: =IFERROR('Valuation Signals'!G9*'McEasy Model'!J10/1000000,"") -> 298.86435 | D44: =IFERROR('Valuation Signals'!G5*'McEasy Model'!J10/1000000,"") -> 580.29554 | E44: Bear / base / bull, left to right. The spread is what an investor is actually underwriting — the ARR figure alone tells them almost nothing.
...

Sheet Conservative Cases
A1: Conservative cases — 2030 revenue $10m and $20m below plan
A2: Re-based month by month from Jul-2026 off observed H1 actuals. Two drivers per revenue level, because a volume miss and a price miss produce opposite conclusions at the same revenue.
A4: Block 1 — why the path diverges from Jul-2026, not from plan
A5: Monthly ARR growth, H1-2026 actual | B5: 3.54% → 2.98% → 2.93% → 2.83% → 2.65% | G5: Decelerating through the half. These are reported actuals, not estimates.
A6: Average observed monthly ARR growth | B6: 0.029856262 | G6: Geometric mean, Jan to Jun 2026.
A7: Jun-2026 actual ARR | B7: 9501627.7 | G7: Last actual month in the model.
A8: Plan Dec-2026 exit ARR | B8: 14398706 | G8: The 2026 target.
A9: Growth the plan needs in Jul-2026 alone | B9: 0.12872671 | G9: A step-change from the observed ~2.7% to nearly 13% in a single month, then about 6% a month for the rest of the year. This is the assumption the conservative cases test.
A10: Dec-2026 exit ARR if observed momentum continues | B10: 11335944
A11: Gap to plan on that basis | B11: =B8/B6-1 -> 4.8226753e+08 | G11: Formula below.
A12: Plan ARR multiple, 2026 exit to 2030 exit | B12: 7.0076228 | G12: The plan's own compounding, applied to a lower starting point.
A13: Implied 2030 ARR at observed momentum | B13: 79438020 | G13: So the $80m case is approximately the CURRENT TRAJECTORY, not an arbitrary haircut, and $90m is a partial-recovery case. That is a far stronger way to present these.
A15: Block 2 — 2030 profit and loss by scenario
A16: USD, year to Dec-2030 | B16: Base — the plan | C16: $90m — fewer vehicles | D16: $90m — lower ARPU | E16: $80m — fewer vehicles | F16: $80m — lower ARPU | G16: Notes
A17: Growth haircut applied from Jul-2026 | B17: 1 | C17: 0.94186133 | D17: 0.94186133 | E17: 0.88682291 | F17: 0.88682291 | G17: One lever: the plan's own monthly ARR growth rates multiplied by h from Jul-2026, solved so FY2030 revenue hits the target.
A18: Total revenue | B18: 1.0189465e+08 | C18: 90000000 | D18: 90000000 | E18: 80000000 | F18: 80000000
A19: SaaS Solutions | B19: 83704058 | C19: 73933468 | D19: 73933468 | E19: 65719137 | F19: 65719137
A20: Spare Part Solutions | B20: 18190596 | C20: 16066532 | D20: 16066532 | E20: 14280863 | F20: 14280863
A21: Cost of revenue — SaaS | B21: 20428538 | C21: 18043852 | D21: 20428538 | E21: 16039010 | F21: 20428538
A22: Cost of revenue — Spare Part | B22: 14335721 | C22: 12661791 | D22: 12661791 | E22: 11254541 | F22: 11254541
A23: Logistic cost | B23: 286714.42 | C23: 286714.42 | D23: 286714.42 | E23: 286714.42 | F23: 286714.42
A24: Sales & marketing | B24: 3404155.4 | C24: 3404155.4 | D24: 3404155.4 | E24: 3404155.4 | F24: 3404155.4
A25: Operational expenses | B25: 9723111.1 | C25: 9723111.1 | D25: 9723111.1 | E25: 9723111.1 | F25: 9723111.1
A26: EBITDA | B26: 53716414 | C26: 45880377 | D26: 43495690 | E26: 39292468 | F26: 34902940
A27: Depreciation | B27: 11575492 | C27: 10851994 | D27: 11575492 | E27: 10227144 | F27: 11575492
A28: Tax & interest | B28: 9327901.5 | C28: 7753539.5 | D28: 7065542.3 | E28: 6433615.2 | F28: 5163535.3
A29: Net profit | B29: 32813020 | C29: 27274843 | D29: 24854656 | E29: 22631709 | F29: 18163913
A30: Capex | B30: 19003126 | C30: 16784165 | D30: 19003126 | E30: 14918722 | F30: 19003126
A31: Gross margin | B31: =IFERROR(((B18-B21-B22)/B18),"") -> 0.65882156 | C31: =IFERROR(((C18-C21-C22)/C18),"") -> 0.65882619 | D31: =IFERROR(((D18-D21-D22)/D18),"") -> 0.63232968 | E31: =IFERROR(((E18-E21-E22)/E18),"") -> 0.65883061 | F31: =IFERROR(((F18-F21-F22)/F18),"") -> 0.60396151
A32: EBITDA margin | B32: =IFERROR(B26/B18,"") -> 0.52717598 | C32: =IFERROR(C26/C18,"") -> 0.50978196 | D32: =IFERROR(D26/D18,"") -> 0.48328545 | E32: =IFERROR(E26/E18,"") -> 0.49115585 | F32: =IFERROR(F26/F18,"") -> 0.43628675
A33: Net margin | B33: =IFERROR(B29/B18,"") -> 0.32202887 | C33: =IFERROR(C29/C18,"") -> 0.30305381 | D33: =IFERROR(D29/D18,"") -> 0.27616285 | E33: =IFERROR(E29/E18,"") -> 0.28289636 | F33: =IFERROR(F29/F18,"") -> 0.22704891
A34: Capex % of revenue | B34: =IFERROR(B30/B18,"") -> 0.18649777 | C34: =IFERROR(C30/C18,"") -> 0.18649072 | D34: =IFERROR(D30/D18,"") -> 0.21114584 | E34: =IFERROR(E30/E18,"") -> 0.18648403 | F34: =IFERROR(F30/F18,"") -> 0.23753907
A35: Sparepart share of revenue (must hold constant) | B35: =IFERROR(B20/B18,"") -> 0.17852355 | C35: =IFERROR(C20/C18,"") -> 0.17851702 | D35: =IFERROR(D20/D18,"") -> 0.17851702 | E35: =IFERROR(E20/E18,"") -> 0.17851078 | F35: =IFERROR(F20/F18,"") -> 0.17851078 | G35: Grady's constraint. Holds at 17.85% in every scenario because the plan's own monthly revenue mix is preserved.
A37: Block 3 — the benchmark check. This is where the two drivers part company.
A38: Vehicles at Dec-2030 | B38: 950000 | C38: 830608.99 | D38: 950000 | E38: 731195.73 | F38: 950000
A39: Revenue per vehicle per month | B39: =IFERROR(B18/B38/12,"") -> 8.9381275 | C39: =IFERROR(C18/C38/12,"") -> 9.0295194 | D39: =IFERROR(D18/D38/12,"") -> 7.8947368 | E39: =IFERROR(E18/E38/12,"") -> 9.1174857 | F39: =IFERROR(F18/F38/12,"") -> 7.0175439 | G39: Vehicles are derived from exit ARR at constant ARR-per-vehicle, so slower growth mechanically lifts this ratio slightly in the volume cases — full-year revenue is measured against a smaller exit base. A definitional artefact, not a price rise.
A40: EBITDA per vehicle per year | B40: =IFERROR(B26/B38,"") -> 56.543594 | C40: =IFERROR(C26/C38,"") -> 55.237034 | D40: =IFERROR(D26/D38,"") -> 45.784937 | E40: =IFERROR(E26/E38,"") -> 53.737278 | F40: =IFERROR(F26/F38,"") -> 36.739937
A41: Cartrack FY2019 EBITDA per subscriber | B41: ='Karooooo Path'!C25*1000000/'Karooooo Path'!C19 -> 57.844253
A42: Gap to the benchmark | B42: =IFERROR(B40/$B$41-1,"") -> -0.022485538 | C42: =IFERROR(C40/$B$41-1,"") -> -0.045073087 | D42: =IFERROR(D40/$B$41-1,"") -> -0.20847906 | E42: =IFERROR(E40/$B$41-1,"") -> -0.071000572 | F42: =IFERROR(F40/$B$41-1,"") -> -0.36484724 | G42: THE FINDING: a volume miss leaves the Cartrack argument intact — EBITDA per vehicle stays within 7% even at $80m. A price miss destroys it, landing 36% below the benchmark you are presenting against. Same revenue, opposite conclusion.
A44: Block 4 — re-based path, 2026 to 2030
...

Sheet Capex Decomposition
A1: Capex per vehicle — decomposed, because the headline gap is the wrong number
A2: Capex is spent on NEW installations, not on the whole base. On the correct denominator the gap is wider, not narrower — and that is fine, because the absolute cost per install is what matters and it is conservative.
A4: Block 1 — the denominator problem
A5: Basis | B5: McEasy 2030 | C5: Cartrack FY2019 | D5: Delta | E5: Why it matters
A6: Capex per vehicle in the BASE | B6: ='McEasy Model'!J31/'McEasy Model'!$B$44 -> 20.00329 | C6: =('Karooooo Path'!C15/'Karooooo Path'!C6*1000000)/'Karooooo Path'!C19 -> 38.532447 | D6: =IFERROR(B6/C6-1,"") -> -0.48087153 | E6: The figure originally shown. It divides a flow (a year's spend) by a stock (the whole installed base), so it is not a unit cost of anything. Do not lead with it.
A7: Net additions in the year | B7: =('McEasy Model'!$B$44-('McEasy Model'!$B$44*'McEasy Model'!I8/'McEasy Model'!J8)) -> 350495.51 | C7: =('Karooooo Path'!C19-'Karooooo Path'!B19) -> 209418 | E7: McEasy's 2029 vehicle count is NOT in the model. It is proxied here by scaling the 2030 count by the ratio of 2029 to 2030 SaaS revenue, i.e. assuming flat ARPU. Replace with the real ramp when you build one.
A8: Capex per NET ADDITION | B8: ='McEasy Model'!J31/('McEasy Model'!$B$44-('McEasy Model'!$B$44*'McEasy Model'!I8/'McEasy Model'!J8)) -> 54.217886 | C8: =('Karooooo Path'!C15/'Karooooo Path'!C6*1000000)/('Karooooo Path'!C19-'Karooooo Path'!B19) -> 176.7847 | D8: =IFERROR(B8/C8-1,"") -> -0.6933112 | E8: The economically correct denominator, and the gap is WIDER here. Concede this before an investor derives it. Then point at Block 2 — the absolute number is conservative.
A10: Block 2 — what one installation actually costs at 2026 prices
A11: Component | B11: Low (USD) | C11: High (USD) | E11: Source / note
A12: 4G Cat-1 basic tracker, volume, landed Indonesia | B12: 15 | C12: 25 | E12: Concox / Jimi IoT wholesale runs USD12-49 with high-volume pricing as low as USD5-12; Teltonika FMB920 is about EUR35 at retail. Replace with your own quotes.
A13: Installation labour, roughly one hour | B13: 8 | C13: 15 | E13: Indonesian technician, fully loaded. Materially below the South African equivalent.
A14: SIM activation, logistics, spares, wastage | B14: 3 | C14: 6 | E14: Estimate — refine from your own actuals.
A15: Bill of materials — one basic tracker install | B15: =SUM(B12:B14) -> 26 | C15: =SUM(C12:C14) -> 46 | E15: Compare against the per-net-add budget above.
A16: Headroom in the model's budget versus the high case | B16: =B8-C15 -> 8.2178861 | E16: Positive means the model is CONSERVATIVE per install, not aggressive. This is the single most useful sentence you can say on this topic.
A17: AI dashcam / video unit install, all-in | B17: 80 | C17: 200 | E17: Materially dearer than a basic tracker.
A18: Maximum dashcam share the budget supports | B18: =IFERROR(MAX(0,(B8-C15)/(AVERAGE(B17,C17)-C15)),"") -> 0.08742432 | E18: At a blended dashcam install cost, this is the share of new installs that can be video units before the capex budget breaks. CHECK THIS AGAINST THE PRODUCT ROADMAP — if video is a bigger part of the 2030 mix, capex is understated.
A20: Block 3 — RESOLVED. Cartrack's actual FY2019 device capex, from Note 5 of the Karooooo F-1
A21: Source: Karooooo Ltd Form F-1 (Mar-2021), Note 5 'Property, plant and equipment' FY2019 movement table, and Note 6 'Capitalized commission assets'. Figures in ZAR thousands as reported; the reconciliation below ties exactly.
A22: FY2019 line item (ZAR 000s) | B22: Amount | C22: % of cash-flow line | E22: Note
A23: Capitalised telematics devices — additions | B23: 353655 | C23: =B23/507151 -> 0.69733669 | E23: Note 5. The device AND its directly related installation costs, capitalised together and depreciated straight-line over the expected average contract life of 60 months. THIS is the figure a device-cost comparison should use.
A24: Other owned-asset additions | B24: 6836 | C24: =B24/507151 -> 0.01347922 | E24: Buildings, furniture and fixtures, leasehold improvements, plant and machinery — ZAR6.8m in total. Immaterial.
A25: Owned-asset additions = cash PP&E capex | B25: 360491 | C25: =B25/507151 -> 0.71081591 | E25: Note 5 total owned additions of ZAR360,491k. Right-of-use additions of ZAR74,364k (IT equipment, motor vehicles, property) are IFRS 16 lease recognitions, not cash capex, and are excluded here.
A26: Cash-flow line: PP&E AND CONTRACT ASSETS | B26: 507151 | C26: =B26/507151 -> 1 | E26: As reported in the FY2019 SENS. This is the figure that produced the USD176.77 per add.
A27: Residual = contract assets / capitalised commissions | B27: 146660 | C27: =B27/507151 -> 0.28918409 | E27: 28.9% of the line. Note 6 confirms a separate 'Capitalized sales commissions' asset — cost ZAR178,330k at Feb-2019. McEasy expenses commissions through S&M, so this has no McEasy equivalent at all.
A29: Restated on device capex only | B29: McEasy 2030 | C29: Cartrack FY2019 | D29: Gap | E29: Note
A30: Device + installation capex per NET ADDITION | B30: =B8 -> 54.217886 | C30: =B23/'Karooooo Path'!C6*1000/('Karooooo Path'!C19-'Karooooo Path'!B19) -> 123.26655 | D30: =IFERROR(B30/C30-1,"") -> -0.56015734 | E30: The gap to defend, correctly stated: device-and-install against device-and-install, per new unit. Down from -69% on the as-reported line.
A31: Device + installation capex per BASE vehicle | B31: ='McEasy Model'!J31/'McEasy Model'!$B$44 -> 20.00329 | C31: =B23/'Karooooo Path'!C6*1000/'Karooooo Path'!C19 -> 26.867493 | D31: =IFERROR(B31/C31-1,"") -> -0.25548356 | E31: On the base-vehicle view the restated gap is modest. This is the most favourable true framing available — and unlike the original -48% it is like-for-like.
A32: Cartrack device depreciation life | B32: 60 months | E32: Disclosed accounting policy: capitalised telematics devices are depreciated straight-line over the expected average contract life of 60 months, reduced where contracts are expected to be materially shorter. CHECK YOUR OWN ASSUMED DEVICE LIFE against this — if yours is longer, that explains part of the depreciation-per-vehicle gap and is a separate assumption to defend.
A34: Block 4 — an internal tension to reconcile before the meeting
A35: Metric | B35: McEasy 2030 | C35: Cartrack FY2019 | E35: Note
A36: Base growth in the year | B36: =IFERROR('McEasy Model'!$B$44/('McEasy Model'!$B$44*'McEasy Model'!I8/'McEasy Model'!J8)-1,"") -> 0.58464202 | C36: =IFERROR('Karooooo Path'!C19/'Karooooo Path'!B19-1,"") -> 0.27871117
A37: Capex as a multiple of depreciation | B37: =IFERROR('McEasy Model'!J31/'McEasy Model'!J23,"") -> 1.6416689 | C37: =IFERROR(('Karooooo Path'!C15/'Karooooo Path'!C6*1000000)/(('Karooooo Path'!C13-'Karooooo Path'!C11)/'Karooooo Path'!C6*1000000),"") -> 1.9395793 | E37: A faster-growing base should carry a HIGHER capex-to-depreciation multiple, because more of the spend is on units not yet depreciated. McEasy grows the base roughly twice as fast as Cartrack did, on a LOWER multiple. Either device life is assumed longer, capex is light, or the vehicle ramp is back-loaded. An investor building a device cohort model will find this.
A39: Block 5 — the justifications, ranked by how well they survive scrutiny
A40: You sell hardware; Cartrack subsidised it | B40: Tier 1 | E40: Sparepart Solutions is USD18.2m of 2030 revenue at a 21.2% gross margin — the signature of pass-through hardware at low markup. A device the customer BUYS is cost of revenue, not capex. Cartrack retained device ownership so its device spend sat in PP&E. Say the flip side yourself: this relocates cost rather than removing it, which is exactly why the blended gross margin is 65.9% against 75.6% SaaS-only, and exactly why EBITDA per vehicle still matches.
A41: Cartrack's line bundles things you do not capitalise — now proven, not asserted | B41: Tier 1 | E41: Note 5 of the Karooooo F-1 shows FY2019 capitalised telematics device additions of ZAR353,655k against a cash-flow line of ZAR507,151k. The ZAR146,660k residual (28.9%) is capitalised sales commissions, which Note 6 carries as a separate asset and which McEasy expenses through S&M. A further ZAR74,364k of right-of-use additions in the note are IFRS 16 lease recognitions, not cash capex. Restating device-for-device closes most of the gap.
A42: Hardware price deflation, 2019 to 2026 | B42: Tier 2 | E42: Listed device vendors are visibly losing pricing power. Queclink FY2025: revenue -7.8%, gross margin 40.1% to 36.9%, operating margin 13.4% to 5.4%. Streamax FY2025: revenue -10.8%. Both on the 'At 100M (Today)' sheet with sources.
A43: Installation labour and asset mix | B43: Tier 2 | E43: Indonesian install labour sits well below South African. Two-wheelers and light assets cost a fraction of a truck unit with CAN bus and video — Queclink discloses a dedicated two-wheeler terminal line precisely because Southeast Asia has that volume.
A44: "We are more capital-efficient operators" | B44: Do not use | E44: Unquantifiable, and it invites the auditor question instead of answering it. Every argument above is either in your own accounts or in a listed company's disclosure. Stay there.
A46: Notes & definitions
A47: What to say: 'our capex is USD54 per new installation against a USD26-46 bill of materials, so we are carrying headroom. Cartrack's USD177 is not comparable — it bundles capitalised commissions and stolen-vehicle-recovery infrastructure we do not operate.' That answers the question instead of defending a percentage.
...

Sheet Growth Reality Check
A1: The assumption that is genuinely more aggressive than the benchmark
A2: It is not the margin. It is delivering a 66% ARR CAGR while turning EBITDA-positive in 2026 and raising no further equity. No company in this peer set has done both at once.
A4: What the plan requires versus what the benchmark delivered
A5: Company / plan | B5: Period | C5: ARR or revenue CAGR | D5: FCF margin | E5: Comment
A6: McEasy — required | B6: 2025-2030 | C6: ='McEasy Model'!$B$53 -> 0.66210063 | E6: ARR from USD7.95m to USD100.9m: a 12.7x increase in five years.
A7: Cartrack — realised | B7: FY2019-FY2026 | C7: =('Karooooo Path'!I24/'Karooooo Path'!C23)^(1/7)-1 -> 0.16605644 | D7: ='Karooooo Path'!I33 -> 0.14765468 | E7: Cartrack's MATURE phase, from USD111m to USD325m. Not the right comparison for McEasy's stage, but it is what the benchmark actually did after the milestone.
A8: Cartrack — at the milestone | B8: FY2019 | C8: ='Karooooo Path'!C8/'Karooooo Path'!B8-1 -> 0.27828123 | D8: ='Karooooo Path'!C33 -> 0.021563183 | E8: Revenue growth in the year it crossed USD100m ARR: 27.8%, with a 2.2% FCF margin. Fast growth and free cash flow did not coexist even here.
A9: Netradyne | B9: 2023-2024 | C9: 0.62 | E9: The only company in the set growing at McEasy's required rate. Private, USD1.3bn valuation, no disclosed profitability, venture-funded.
A10: Motive | B10: LTM Sep-2025 | C10: 0.28 | D10: -0.23 | E10: Grew to USD501m ARR and still burns 23% of revenue. Filed to IPO in Dec-2025 and remains unpriced. This is what funding hypergrowth looks like.
A11: Karooooo | B11: FY2026 | C11: 0.1997 | E11: 20% growth at a 42% EBITDA margin and positive free cash flow — the profitable-growth case, at a third of McEasy's required rate.
A12: Quartix | B12: FY2025 | C12: 0.123 | D12: 0.1252 | E12: Profitable and slow. 2.93x sales.
A13: Microlise | B13: FY2025 | C13: 0.057 | D13: 0.1127 | E13: Slow AND unprofitable. 0.39x sales.
A14: McEasy's required rate as a multiple of Cartrack's realised rate | C14: =IFERROR(C6/C7,"") -> 3.9872025 | E14: In fairness: 66% off a USD7.95m base is a very different proposition from 66% off USD100m, and Cartrack's own growth at USD8m of ARR is not disclosed. The honest framing is that McEasy needs Netradyne-class growth with Cartrack-class margins.
A16: Funding: the plan self-funds from 2026 onward
A17: Year | B17: Cash at year end (USD) | C17: EBITDA (USD) | D17: Paid-up capital (USD) | E17: Comment
A18: 2025 | B18: ='McEasy Model'!E29 -> 1915277.6 | C18: ='McEasy Model'!E22 -> -1604798.7 | D18: ='McEasy Model'!E30 -> 15655051 | E18: Thinnest point in the plan: cash of USD1.9m against a USD1.6m EBITDA loss — under twelve months of runway before the 2026 raise.
A19: 2026 | B19: ='McEasy Model'!F29 -> 3795656.1 | C19: ='McEasy Model'!F22 -> 1377091.8 | D19: ='McEasy Model'!F30 -> 20086600 | E19: Paid-up capital rises USD4.43m and EBITDA turns positive in the same year. Both have to happen; the plan has no slack if either slips.
A20: 2027 | B20: ='McEasy Model'!G29 -> 4378637.3 | C20: ='McEasy Model'!G22 -> 6383868.8 | D20: ='McEasy Model'!G30 -> 20086600 | E20: Last year of low cash. From here the model is self-funding.
A21: 2028 | B21: ='McEasy Model'!H29 -> 12171358 | C21: ='McEasy Model'!H22 -> 16048954 | D21: ='McEasy Model'!H30 -> 20086600
A22: 2029 | B22: ='McEasy Model'!I29 -> 25098319 | C22: ='McEasy Model'!I22 -> 30182959 | D22: ='McEasy Model'!I30 -> 20086600
A23: 2030 | B23: ='McEasy Model'!J29 -> 42418799 | C23: ='McEasy Model'!J22 -> 53716414 | D23: ='McEasy Model'!J30 -> 20086600 | E23: USD42.4m of cash and no equity raised since 2026.
A25: Notes & definitions
A26: The investor question this sheet exists to answer: 'you are asking me to believe you will grow four times faster than Cartrack did and reach better unit economics than Cartrack ever had, without raising again.' Blocks 2 and 3 of the benchmark sheet answer the unit-economics half. This sheet is where you should concede that the growth half is the genuine risk, and show the bear case is survivable.
A27: The single most useful thing you can add to the model before the meeting is a year-by-year vehicle and ARPU build. Without it, the 66% CAGR is an assertion; with it, it becomes a sales capacity and installation-throughput question that you can actually defend with an operating plan.

Sheet McEasy Model
A1: McEasy's own model, as supplied — read directly from the source file
A2: Blue = taken verbatim from 'McEasy model for claude reading.xlsx'. Yellow = the volume assumption Grady supplied in conversation, which is NOT in the model. Nothing on the benchmark sheets hardcodes a McEasy number; they all point here.
A4: Line item (USD) | B4: 2022 | C4: 2023 | D4: 2024 | E4: 2025 | F4: 2026 | G4: 2027 | H4: 2028 | I4: 2029 | J4: 2030
A5: Status per the model | B5: Actual | C5: Actual | D5: Actual | E5: Actual | F5: Projection | G5: Projection | H5: Projection | I5: Projection | J5: Projection
A6: Profit and loss, as modelled
A7: ARR | B7: 971426.11 | C7: 2454952.9 | D7: 4663990.4 | E7: 7954403.2 | F7: 14398706 | G7: 26164255 | H7: 41096544 | I7: 64090664 | J7: 1.009007e+08
A8: Revenue — SaaS Solutions | B8: 551706.33 | C8: 1700156.8 | D8: 3297397.3 | E8: 6059842.3 | F8: 10545545 | G8: 20361874 | H8: 33907054 | I8: 52822062 | J8: 83704058
A9: Revenue — Sparepart Solutions | B9: =B10-B8 -> 0 | C9: =C10-C8 -> 0 | D9: =D10-D8 -> 301146.1 | E9: =E10-E8 -> 1515014.6 | F9: =F10-F8 -> 1796432.7 | G9: =G10-G8 -> 3406338.5 | H9: =H10-H8 -> 6347739.5 | I9: =I10-I8 -> 11319457 | J9: =J10-J8 -> 18190596
A10: Total Revenue | B10: 551706.33 | C10: 1700156.8 | D10: 3598543.4 | E10: 7574856.9 | F10: 12341977 | G10: 23768213 | H10: 40254794 | I10: 64141519 | J10: 1.0189465e+08
A11: Total Cost of Revenue | B11: 160287.97 | C11: 400746.91 | D11: 1035087.4 | E11: 2814571.6 | F11: 4060835.7 | G11: 7918430 | H11: 13385958 | I11: 21781037 | J11: 34764259
A12: Total Gross Profit | B12: 391418.36 | C12: 1299409.9 | D12: 2563456 | E12: 4760285.4 | F12: 8281141.8 | G12: 15849783 | H12: 26868836 | I12: 42360481 | J12: 67130395
A13: Logistic Cost | B13: 0 | C13: 0 | D13: 6031.0455 | E13: 44517.615 | F13: 30248.4 | G13: 58942.469 | H13: 102331.29 | I13: 178563.17 | J13: 286714.42
A14: Sales & Marketing Costs | B14: 364088.49 | C14: 833858.49 | D14: 1140042.6 | E14: 1184089.2 | F14: 1249396.8 | G14: 1775645.9 | H14: 2233706.6 | I14: 2823461.8 | J14: 3404155.4
A15: Contribution Margin | B15: 27329.875 | C15: 465551.37 | D15: 1417382.4 | E15: 3531678.5 | F15: 7001496.7 | G15: 14015194 | H15: 24532798 | I15: 39358456 | J15: 63439525
A16: Personnel Expenses | B16: 764893.78 | C16: 1485357.2 | D16: 1972518.5 | E16: 2811910.9 | F16: 3101906.4 | G16: 4107765.9 | H16: 4537471.3 | I16: 4931047.2 | J16: 5351772.8
A17: General & Administrative Expenses | B17: 570530.78 | C17: 900014.43 | D17: 1265911.2 | E17: 1613489.9 | F17: 1870083 | G17: 2255305.6 | H17: 2459328.1 | I17: 2684125.7 | J17: 2850604.1
A18: Marketing Expenses | B18: 31846.695 | C18: 84200.177 | D18: 91445.796 | E18: 84482.067 | F18: 70842.281 | G18: 83600 | H18: 239380 | I18: 243349 | J18: 127516.45
A19: Technology Expenses | B19: 189333.2 | C19: 293221.56 | D19: 515230.31 | E19: 609794.29 | F19: 566381.76 | G19: 1170102.4 | H19: 1233112.7 | I19: 1302424 | J19: 1378666.4
A20: Other Expenses (Income) | B20: 40836.929 | C20: -17481.927 | D20: -15053.583 | E20: 16800.051 | F20: 15191.48 | G20: 14551.449 | H20: 14551.449 | I20: 14551.449 | J20: 14551.449
A21: Total Operational Expenses | B21: 1597441.4 | C21: 2745311.4 | D21: 3830052.3 | E21: 5136477.2 | F21: 5624404.9 | G21: 7631325.4 | H21: 8483843.6 | I21: 9175497.4 | J21: 9723111.1
... A25: Net Profit (Loss) | B25: -1791502.1 | C25: -2760503.3 | D25: -3266212.2 | E25: -2820272.9 | F25: -461538.23 | G25: 3135502.6 | H25: 9905019.3 | I25: 17611156 | J25: 32813020
A27: From the balance sheet
A28: Fixed assets, gross | C28: 1942180.3 | D28: 3009920.2 | E28: 5206461.8 | F28: 8177674.8 | G28: 13932211 | H28: 20935430 | I28: 32180322 | J28: 51183448
A29: Cash and cash equivalents | C29: 1418750.8 | D29: 3168339.1 | E29: 1915277.6 | F29: 3795656.1 | G29: 4378637.3 | H29: 12171358 | I29: 25098319 | J29: 42418799
A30: Paid-up capital | C30: 8030051.4 | D30: 12655051 | E30: 15655051 | F30: 20086600 | G30: 20086600 | H30: 20086600 | I30: 20086600 | J30: 20086600
A31: Capex (year-on-year change in gross fixed assets) | D31: =IF(COUNT(D28,C28)=2,D28-C28,"") -> 1067739.9 | E31: =IF(COUNT(E28,D28)=2,E28-D28,"") -> 2196541.5 | F31: =IF(COUNT(F28,E28)=2,F28-E28,"") -> 2971213.1 | G31: =IF(COUNT(G28,F28)=2,G28-F28,"") -> 5754535.8 | H31: =IF(COUNT(H28,G28)=2,H28-G28,"") -> 7003219.6 | I31: =IF(COUNT(I28,H28)=2,I28-H28,"") -> 11244892 | J31: =IF(COUNT(J28,I28)=2,J28-I28,"") -> 19003126
A33: Margins and ratios (calculated)
A34: Gross margin | B34: =IF(COUNT(B12,B10)=2,B12/B10,"") -> 0.70946868 | C34: =IF(COUNT(C12,C10)=2,C12/C10,"") -> 0.76428826 | D34: =IF(COUNT(D12,D10)=2,D12/D10,"") -> 0.71235934 | E34: =IF(COUNT(E12,E10)=2,E12/E10,"") -> 0.62843238 | F34: =IF(COUNT(F12,F10)=2,F12/F10,"") -> 0.67097366 | G34: =IF(COUNT(G12,G10)=2,G12/G10,"") -> 0.6668479 | H34: =IF(COUNT(H12,H10)=2,H12/H10,"") -> 0.66746922 | I34: =IF(COUNT(I12,I10)=2,I12/I10,"") -> 0.66042218 | J34: =IF(COUNT(J12,J10)=2,J12/J10,"") -> 0.65882156
A35: Contribution margin | B35: =IF(COUNT(B15,B10)=2,B15/B10,"") -> 0.049536998 | C35: =IF(COUNT(C15,C10)=2,C15/C10,"") -> 0.2738285 | D35: =IF(COUNT(D15,D10)=2,D15/D10,"") -> 0.39387669 | E35: =IF(COUNT(E15,E10)=2,E15/E10,"") -> 0.466237 | F35: =IF(COUNT(F15,F10)=2,F15/F10,"") -> 0.56729132 | G35: =IF(COUNT(G15,G10)=2,G15/G10,"") -> 0.58966126 | H35: =IF(COUNT(H15,H10)=2,H15/H10,"") -> 0.60943792 | I35: =IF(COUNT(I15,I10)=2,I15/I10,"") -> 0.61361903 | J35: =IF(COUNT(J15,J10)=2,J15/J10,"") -> 0.62259915
A36: Total operational expenses % of revenue | B36: =IF(COUNT(B21,B10)=2,B21/B10,"") -> 2.895456 | C36: =IF(COUNT(C21,C10)=2,C21/C10,"") -> 1.6147401 | D36: =IF(COUNT(D21,D10)=2,D21/D10,"") -> 1.064334 | E36: =IF(COUNT(E21,E10)=2,E21/E10,"") -> 0.67809561 | F36: =IF(COUNT(F21,F10)=2,F21/F10,"") -> 0.45571343 | G36: =IF(COUNT(G21,G10)=2,G21/G10,"") -> 0.32107275 | H36: =IF(COUNT(H21,H10)=2,H21/H10,"") -> 0.21075362 | I36: =IF(COUNT(I21,I10)=2,I21/I10,"") -> 0.14305083 | J36: =IF(COUNT(J21,J10)=2,J21/J10,"") -> 0.095423172
A37: EBITDA margin | B37: =IF(COUNT(B22,B10)=2,B22/B10,"") -> -2.845919 | C37: =IF(COUNT(C22,C10)=2,C22/C10,"") -> -1.3409117 | D37: =IF(COUNT(D22,D10)=2,D22/D10,"") -> -0.67045735 | E37: =IF(COUNT(E22,E10)=2,E22/E10,"") -> -0.21185861 | F37: =IF(COUNT(F22,F10)=2,F22/F10,"") -> 0.11157789 | G37: =IF(COUNT(G22,G10)=2,G22/G10,"") -> 0.26858851 | H37: =IF(COUNT(H22,H10)=2,H22/H10,"") -> 0.3986843 | I37: =IF(COUNT(I22,I10)=2,I22/I10,"") -> 0.4705682 | J37: =IF(COUNT(J22,J10)=2,J22/J10,"") -> 0.52717598
A38: Depreciation % of revenue | B38: =IF(COUNT(B23,B10)=2,B23/B10,"") -> 0.26218225 | C38: =IF(COUNT(C23,C10)=2,C23/C10,"") -> 0.24278535 | D38: =IF(COUNT(D23,D10)=2,D23/D10,"") -> 0.2090374 | E38: =IF(COUNT(E23,E10)=2,E23/E10,"") -> 0.14937028 | F38: =IF(COUNT(F23,F10)=2,F23/F10,"") -> 0.14128172 | G38: =IF(COUNT(G23,G10)=2,G23/G10,"") -> 0.13348227 | H38: =IF(COUNT(H23,H10)=2,H23/H10,"") -> 0.12473442 | I38: =IF(COUNT(I23,I10)=2,I23/I10,"") -> 0.1174217 | J38: =IF(COUNT(J23,J10)=2,J23/J10,"") -> 0.11360255
A39: Capex % of revenue | B39: =IF(COUNT(B31,B10)=2,B31/B10,"") | C39: =IF(COUNT(C31,C10)=2,C31/C10,"") | D39: =IF(COUNT(D31,D10)=2,D31/D10,"") -> 0.29671448 | E39: =IF(COUNT(E31,E10)=2,E31/E10,"") -> 0.28997795 | F39: =IF(COUNT(F31,F10)=2,F31/F10,"") -> 0.24074044 | G39: =IF(COUNT(G31,G10)=2,G31/G10,"") -> 0.24211058 | H39: =IF(COUNT(H31,H10)=2,H31/H10,"") -> 0.17397231 | I39: =IF(COUNT(I31,I10)=2,I31/I10,"") -> 0.17531378 | J39: =IF(COUNT(J31,J10)=2,J31/J10,"") -> 0.18649777
A40: Net margin | B40: =IF(COUNT(B25,B10)=2,B25/B10,"") -> -3.2472023 | C40: =IF(COUNT(C25,C10)=2,C25/C10,"") -> -1.6236757 | D40: =IF(COUNT(D25,D10)=2,D25/D10,"") -> -0.90764841 | E40: =IF(COUNT(E25,E10)=2,E25/E10,"") -> -0.37232029 | F40: =IF(COUNT(F25,F10)=2,F25/F10,"") -> -0.037395809 | G40: =IF(COUNT(G25,G10)=2,G25/G10,"") -> 0.13192 | H40: =IF(COUNT(H25,H10)=2,H25/H10,"") -> 0.24605813 | I40: =IF(COUNT(I25,I10)=2,I25/I10,"") -> 0.27456719 | J40: =IF(COUNT(J25,J10)=2,J25/J10,"") -> 0.32202887
A41: ARR growth year on year | C41: =IFERROR(C7/B7-1,"") -> 1.5271638 | D41: =IFERROR(D7/C7-1,"") -> 0.89982884 | E41: =IFERROR(E7/D7-1,"") -> 0.70549306 | F41: =IFERROR(F7/E7-1,"") -> 0.81015537 | G41: =IFERROR(G7/F7-1,"") -> 0.81712549 | H41: =IFERROR(H7/G7-1,"") -> 0.57071331 | I41: =IFERROR(I7/H7-1,"") -> 0.55951469 | J41: =IFERROR(J7/I7-1,"") -> 0.57434317
A43: Volume assumption — SUPPLIED BY GRADY, NOT PRESENT IN THE MODEL
A44: Vehicles at 2030 — central case | B44: 950000 | C44: Grady stated ~900k-1m vehicles at USD8-9 per vehicle per month for 2030. The two sheets in the model contain no subscriber, vehicle or ARPU driver at all. Every per-vehicle figure in this workbook flows from this single yellow cell — change it and the whole benchmark reflows. Turning this into a modelled year-by-year build is the highest-value fix to the model itself.
A45: Vehicles at 2030 — low case | B45: 900000
A46: Vehicles at 2030 — high case | B46: 1000000
A47: Implied total revenue per vehicle per month | B47: =IFERROR(J10/'McEasy Model'!$B$44/12,"") -> 8.9381275 | C47: Must land inside the USD8-9 band Grady stated for the total line.
...

Sheet At 100M (Today)
A1: Who is at this size RIGHT NOW — FMS / telematics, revenue USD80-250m
A2: Same columns as 'Current Position' so the two read side by side. Native reporting currency is kept alongside USD so nothing is hidden inside an FX conversion.
A4: Company | B4: Listing / ownership | C4: Fiscal period | D4: Currency | E4: ARR (USD m) | F4: Distance from USD100m ARR | G4: Total revenue (USD m) | H4: Recurring revenue (USD m) | I4: Recurring % of revenue | J4: Revenue growth YoY | K4: Subscribers / units | L4: Employees | M4: Revenue per employee (USD k) | N4: Gross margin | O4: Operating margin | P4: Net margin | Q4: EBITDA margin | R4: FCF (USD m) | S4: FCF margin | T4: Confidence | U4: Notes
A5: Block A — subscription-FMS operators, revenue USD80-250m (the primary comparison)
A6: Microlise | B6: AIM: SAAS (listed UK) | C6: FY2025 (Dec-25) | D6: GBP | E6: =59.2*Assumptions!$B$13 -> 78.0848 | F6: =IF(COUNT(E6)=1,E6-Assumptions!$B$15,"") -> -21.9152 | G6: =84.03*Assumptions!$B$13 -> 110.83557 | H6: =58.8*Assumptions!$B$13 -> 77.5572 | I6: =IF(COUNT(H6,G6)=2,H6/G6,"") -> 0.69975009 | J6: 0.057 | L6: 615 | M6: =IF(COUNT(G6,L6)=2,G6*1000/L6,"") -> 180.22044 | N6: 0.6442937 | O6: -0.028799238 | P6: -0.02582411 | Q6: 0.1 | R6: =9.47*Assumptions!$B$13 -> 12.49093 | S6: =IF(COUNT(R6,G6)=2,R6/G6,"") -> 0.11269785 | T6: H | U6: The anchor of this sheet and the most uncomfortable row in the workbook. ARR GBP59.2m (+4.6%), 64% gross margin, 1.4% churn, 417 new customers — and a STATUTORY OPERATING LOSS. The 10% figure is adjusted EBITDA, down from 14%. Enterprise value is GBP32m against GBP84m of revenue: 0.39x sales. Headcount also reported as ~730 across UK, France, Australia and India before announced cuts.
A7: ORBCOMM | B7: Private (GI Partners, 2021 LBO) | C7: TTM to Sep-25 | D7: USD | F7: =IF(COUNT(E7)=1,E7-Assumptions!$B$15,"") | G7: 250 | I7: =IF(COUNT(H7,G7)=2,H7/G7,"") | L7: 878 | M7: =IF(COUNT(G7,L7)=2,G7*1000/L7,"") -> 284.73804 | S7: =IF(COUNT(R7,G7)=2,R7/G7,"") | T7: L | U7: Top of the band at ~USD250m revenue. Taken private in April 2021 at ~USD1.1bn including net debt. No margin, ARR or geographic disclosure since. Included for scale and the buyout multiple only.
A8: CalAmp | B8: Private (Lynrock Lake, post-Ch11) | C8: CY2024 | D8: USD | F8: =IF(COUNT(E8)=1,E8-Assumptions!$B$15,"") | G8: 197 | H8: 126.9 | I8: =IF(COUNT(H8,G8)=2,H8/G8,"") -> 0.64416244 | K8: 2700000 | L8: 644 | M8: =IF(COUNT(G8,L8)=2,G8*1000/L8,"") -> 305.90062 | Q8: 0.064467005 | S8: =IF(COUNT(R8,G8)=2,R8/G8,"") | T8: M | U8: The cautionary row. Reached ~USD200m revenue and 2.7m subscribers, then filed a pre-packaged Chapter 11 in June 2024 that wiped out USD230m of debt AND the public equity; delisted October 2024. EBITDA margin of 6.4% could not service the balance sheet. Headcount is as at Feb-2023, the last 10-K.
A9: Teletrac Navman | B9: Private (Respida Capital, Jun-2026) | C9: CY2026 | D9: USD | F9: =IF(COUNT(E9)=1,E9-Assumptions!$B$15,"") | G9: 168 | I9: =IF(COUNT(H9,G9)=2,H9/G9,"") | M9: =IF(COUNT(G9,L9)=2,G9*1000/L9,"") | S9: =IF(COUNT(R9,G9)=2,R9/G9,"") | T9: L | U9: The valuation row. Vontier sold the majority to Respida Capital, completing 30-Jun-2026 at a total transaction value of USD220m — roughly 1.3x revenue — with only ~USD80m of cash proceeds to Vontier. A strategic owner exiting a USD168m-revenue FMS business at about one and a third times sales.
A10: Netradyne | B10: Private (VC; USD1.3bn valuation) | C10: CY2024-25 | D10: USD | E10: 210 | F10: =IF(COUNT(E10)=1,E10-Assumptions!$B$15,"") -> 110 | I10: =IF(COUNT(H10,G10)=2,H10/G10,"") | J10: 0.62 | L10: 1000 | M10: =IF(COUNT(G10,L10)=2,G10*1000/L10,"") | S10: =IF(COUNT(R10,G10)=2,R10/G10,"") | T10: L | U10: Above the band and growing fastest here: ARR USD210m in 2024 from USD129.8m in 2023, +62%. Valued at USD1.3bn on the 2025 Series D, ~6.2x ARR. Single product family (AI video safety). No margin disclosure. US-weighted with a large India engineering base.
A12: Block B — hardware / device vendors. NOT ARR comparables: these are suppliers to companies like McEasy, shown to expose where the device margin pool sits
A13: Queclink | B13: SHE: 300590 (listed China) | C13: FY2025 (Dec-25) | D13: CNY | F13: =IF(COUNT(E13)=1,E13-Assumptions!$B$15,"") | G13: =891.1/Assumptions!$B$14 -> 123.98258 | I13: =IF(COUNT(H13,G13)=2,H13/G13,"") | J13: -0.078 | L13: 570 | M13: =IF(COUNT(G13,L13)=2,G13*1000/L13,"") -> 217.5133 | N13: 0.36939737 | O13: 0.054438335 | P13: 0.083671866 | R13: =45.79/Assumptions!$B$14 -> 6.3709599 | S13: =IF(COUNT(R13,G13)=2,R13/G13,"") -> 0.051385928 | T13: H | U13: Squarely in the band at ~USD124m revenue, and squarely a device business: 37% gross margin, and operating margin collapsed from 13.4% to 5.4% in one year on a 7.8% revenue decline. 94% of revenue is earned outside China. Discloses a two-wheeler terminal line — directly relevant to Indonesian fleet mix.
A14: Streamax | B14: SZ: 002970 (listed China) | C14: FY2025 (Dec-25) | D14: CNY | F14: =IF(COUNT(E14)=1,E14-Assumptions!$B$15,"") | G14: =2477/Assumptions!$B$14 -> 344.63568 | I14: =IF(COUNT(H14,G14)=2,H14/G14,"") | J14: -0.108 | L14: 2231 | M14: =IF(COUNT(G14,L14)=2,G14*1000/L14,"") -> 154.47587 | N14: 0.44852644 | O14: 0.15139281 | P14: 0.15462253 | R14: =294/Assumptions!$B$14 -> 40.905486 | S14: =IF(COUNT(R14,G14)=2,R14/G14,"") -> 0.11869197 | T14: H | U14: ABOVE the band at ~USD345m revenue — kept because it is the most Southeast-Asia-relevant listed player at any scale, with 65% overseas revenue and 5m+ vehicles. Note the shape: revenue FELL 10.8% while gross margin rose from 35.0% to 44.8% and net margin reached 15.5%. Deliberately traded volume for margin.
A16: Block C — below the band, but the closest business models to McEasy
A17: Quartix | B17: AIM: QTX (listed UK) | C17: FY2025 (Dec-25) | D17: GBP | E17: =37*Assumptions!$B$13 -> 48.803 | F17: =IF(COUNT(E17)=1,E17-Assumptions!$B$15,"") -> -51.197 | G17: =35.71*Assumptions!$B$13 -> 47.10149 | H17: =35.71*Assumptions!$B$13 -> 47.10149 | I17: =IF(COUNT(H17,G17)=2,H17/G17,"") -> 1 | J17: 0.123 | K17: 310701 | L17: 173 | M17: =IF(COUNT(G17,L17)=2,G17*1000/L17,"") -> 272.26295 | N17: 0.73172781 | O17: 0.24306917 | P17: 0.17866144 | R17: =4.47*Assumptions!$B$13 -> 5.89593 | S17: =IF(COUNT(R17,G17)=2,R17/G17,"") -> 0.12517502 | T17: H | U17: The purest SMB-subscription telematics comparable that exists, and profitable at half the target size: 73% gross margin, 24% operating margin, 18% net margin, 12.5% FCF margin on ~USD47m of revenue. 310,701 subscriptions across 31,040 customers. Proof that this model works well below USD100m — and that scale is not what creates margin. Headcount 173 is a third-party estimate.
A18: Fleetio | B18: Private (VC; USD1.5bn valuation) | C18: CY2025 | D18: USD | F18: =IF(COUNT(E18)=1,E18-Assumptions!$B$15,"") | G18: 58 | I18: =IF(COUNT(H18,G18)=2,H18/G18,"") | K18: 8500 | L18: 463 | M18: =IF(COUNT(G18,L18)=2,G18*1000/L18,"") -> 125.26998 | S18: =IF(COUNT(R18,G18)=2,R18/G18,"") | T18: L | U18: The valuation counterpoint to Teletrac Navman. Raised USD450m+ Series D in March 2025 and acquired Auto Integrate; combined business valued above USD1.5bn on roughly USD58m of revenue — about 26x sales, versus Teletrac's 1.3x. 8,500+ fleets, 8m+ vehicles serviced. Revenue is a third-party estimate and the weakest number on this sheet. Subscribers column is fleets, not vehicles.
A20: Notes & definitions
A21: Read this sheet against 'At 100M (Historic)'. Cartrack at USD111m ARR in FY2019 ran a 45% EBITDA margin and a 21% net margin. Microlise at USD78m ARR today runs a 10% ADJUSTED EBITDA margin and a statutory operating loss. Same revenue scale, same industry, opposite economics — the difference is the market and the pricing power, not the size.
A22: Recurring % of revenue is blank where recurring revenue is not disclosed. It is not zero. Quartix's recurring figure equals total revenue because it reports no separate hardware line, not because a split was assumed.
A23: Currency column matters. GBP figures are multiplied by the GBP/USD rate on 'Assumptions'; CNY figures are divided by the USD/CNY rate. Every USD cell here is a live formula over the native reported number, so changing an FX assumption reflows the whole sheet.
A24: Microlise margins are STATUTORY (gross 64.4%, operating -2.9%, net -2.6%) with the company's own adjusted EBITDA margin of 10% shown in the EBITDA column. Mixing statutory and adjusted in one row is deliberate: the gap between them is the point.
A25: Blocks B and C are labelled because they are not like-for-like. Block B sells devices to operators; Block C is below the size band. Neither should be averaged into Block A.

Sheet At 100M (Historic)
A1: Comparables — at the moment they crossed ~USD100m ARR
A2: This is the real benchmark for a 2030 target of USD100m ARR. Note how different these columns look from the 'Current Position' sheet — particularly free-cash-flow margin.
A4: Company | B4: Fiscal period at ~USD100m ARR | C4: Years from founding | D4: Recurring revenue (USD m) | E4: Total revenue (USD m) | F4: Revenue growth YoY | G4: Subscribers | H4: ARPU (USD per subscriber per month) | I4: Employees | J4: Gross margin | K4: Operating margin | L4: Net margin | M4: EBITDA margin | N4: Capex % of revenue | O4: FCF margin | P4: Home market % of revenue | Q4: Confidence | R4: Notes
A5: Karooooo (Cartrack) | B5: FY2019 (Feb-19) | C5: 15 | D5: ='Karooooo Path'!C23 -> 110.9854 | E5: ='Karooooo Path'!C22 -> 123.55474 | F5: =IF(COUNT('Karooooo Path'!C8,'Karooooo Path'!B8)=2,'Karooooo Path'!C8/'Karooooo Path'!B8-1,"") -> 0.27828123 | G5: ='Karooooo Path'!C19 -> 960798 | H5: ='Karooooo Path'!C39 -> 9.6261477 | K5: ='Karooooo Path'!C30 -> 0.29532699 | L5: ='Karooooo Path'!C31 -> 0.21326874 | M5: ='Karooooo Path'!C32 -> 0.44981391 | N5: ='Karooooo Path'!C34 -> 0.29963963 | O5: ='Karooooo Path'!C33 -> 0.021563183 | P5: ='Revenue by Country'!F5 -> 0.73596833 | Q5: H | R5: The benchmark row. 45% EBITDA margin and 21% net margin, but free cash flow was close to nil because capex ran at 30% of revenue — the hardware-subsidy model converts almost all EBITDA into installed devices. Gross margin was not disclosed in the FY2019 release.
A6: Ituran | B6: ~CY2007 | C6: 12 | E6: 114 | F6: 0.17 | G6: 407000 | I6: 800 | Q6: L | R6: Revenue annualised from Q2-2007 of USD29.2m. ~800 staff as at 2006, 407k subscribers in 2007. Pre-2008 disclosure is thin; margins not retrieved. Directional only.
A7: Powerfleet (via MiX Telematics) | B7: FY2014 (Mar-14) | C7: 18 | D7: 81 | E7: 126 | F7: 0.2 | G7: 448000 | M7: 0.215 | Q7: M | R7: MiX Telematics (merged into Powerfleet in 2024) is the only lineage in Powerfleet that organically crossed USD100m. Figures are FY2014 guidance at the midpoint: revenue ZAR1,270-1,300m, subscription ZAR825-833m, adjusted EBITDA ZAR270-280m. EBITDA margin of ~21.5% at this scale versus Cartrack's 45% — the clearest illustration that USD100m ARR says nothing about profitability.
A8: Motive (as KeepTruckin) | B8: ~CY2019 | C8: 6 | P8: 0.9 | Q8: L | R8: Crossed ~USD100m ARR around 2019 (55k+ customers as at Apr-2019; USD150m ARR by 2021). Raised a USD149m Series D in 2019. No margin or headcount disclosure exists for that year — the company was private and deeply loss-making. The fastest to USD100m in this set by a wide margin, and still unprofitable seven years later.
A9: Geotab | B9: ~CY2013 (est.) | C9: 13 | Q9: L | R9: No historical disclosure. Founded 2000; reached USD412m by 2021. Included for completeness only.
A10: Lytx | B10: ~CY2013 (est.) | C10: 15 | Q10: L | R10: No historical disclosure.
A11: Gurtam | B11: Not reached | Q11: H | R11: At USD37.3m revenue in 2025, Gurtam has never approached USD100m. It is the useful counter-example: a profitable, capital-light platform business that chose not to chase scale.
A13: Notes & definitions
A14: Blank cells are honest. For four of the seven companies the USD100m-ARR year predates any meaningful public disclosure. Cartrack FY2019 is the only fully-populated row, which is why it should be McEasy's primary north star and the rest are context.
A15: The pattern that matters: time-to-USD100m ranged from 6 years (Motive, venture-funded, unprofitable) to 18 years (MiX Telematics). EBITDA margin at that milestone ranged from ~21% (MiX) to 45% (Cartrack) to deeply negative (Motive). USD100m ARR is not one destination — it is at least three different businesses.
A16: Cartrack's ~2% FCF margin at USD100m ARR is the number to internalise. High EBITDA plus 30% capex-to-revenue equals no free cash. Any 2030 plan that assumes USD100m ARR funds itself needs to be tested against this row.

